<?xml version="1.0" ?>
<robot name="hook">
  <joint name="hook__arm_JOINT_2" type="revolute">
    <parent link="hook__arm"/>
    <child link="hook__basejoint"/>
    <origin rpy="0  0  0" xyz="0.11  0    0.1"/>
    <axis xyz="0  1  0"/>
    <limit effort="-1.0" lower="0.0" upper="1.8" velocity="-1.0"/>
  </joint>
  <joint name="hook__arm_JOINT_3" type="fixed">
    <parent link="hook__arm"/>
    <child link="hook__armjoint"/>
    <origin rpy="0  0  0" xyz="-0.105  0     0.1"/>
    <axis xyz="0  0  0"/>
    <limit effort="0" lower="0" upper="0" velocity="0"/>
  </joint>
  <joint name="hook__base_JOINT_1" type="fixed">
    <parent link="hook__base"/>
    <child link="hook__basejoint"/>
    <origin rpy="0  0  0" xyz="0     0    -0.019"/>
    <axis xyz="0  0  0"/>
    <limit effort="0" lower="0" upper="0" velocity="0"/>
  </joint>
  <joint name="hook__base_mount_JOINT_0" type="fixed">
    <parent link="hook__base_mount"/>
    <child link="hook__base"/>
    <origin rpy="0  0  0" xyz="0.11   0     0.119"/>
    <axis xyz="0  0  0"/>
    <limit effort="0" lower="0" upper="0" velocity="0"/>
  </joint>
  <joint name="hook__bone1_JOINT_4" type="revolute">
    <parent link="hook__bone1"/>
    <child link="hook__armjoint"/>
    <origin rpy="0  0  0" xyz="-0.105  0     0.1"/>
    <axis xyz="0  1  0"/>
    <limit effort="-1.0" lower="-1.57" upper="0.0" velocity="-1.0"/>
  </joint>
  <joint name="hook__bone1_JOINT_5" type="fixed">
    <parent link="hook__bone1"/>
    <child link="hook__bone1joint"/>
    <origin rpy="0  0  0" xyz="-0.105   0      0.0125"/>
    <axis xyz="0  0  0"/>
    <limit effort="0" lower="0" upper="0" velocity="0"/>
  </joint>
  <joint name="hook__bone2_JOINT_6" type="fixed">
    <parent link="hook__bone2"/>
    <child link="hook__bone1joint"/>
    <origin rpy="0  0  0" xyz="-0.105   0      0.0125"/>
    <axis xyz="0  0  0"/>
    <limit effort="0" lower="0" upper="0" velocity="0"/>
  </joint>
  <joint name="hook__bone2_JOINT_7" type="fixed">
    <parent link="hook__bone2"/>
    <child link="hook__bone2joint"/>
    <origin rpy="0  0  0" xyz="-0.045   0      0.0125"/>
    <axis xyz="0  0  0"/>
    <limit effort="0" lower="0" upper="0" velocity="0"/>
  </joint>
  <joint name="hook__bone3_JOINT_8" type="fixed">
    <parent link="hook__bone3"/>
    <child link="hook__bone2joint"/>
    <origin rpy="0  0  0" xyz="-0.045   0      0.0125"/>
    <axis xyz="0  0  0"/>
    <limit effort="0" lower="0" upper="0" velocity="0"/>
  </joint>
  <joint name="hook__bone3_JOINT_9" type="fixed">
    <parent link="hook__bone3"/>
    <child link="hook__bone3tip"/>
    <origin rpy="0  0  0" xyz="-0.045   0      0.0625"/>
    <axis xyz="0  0  0"/>
    <limit effort="0" lower="0" upper="0" velocity="0"/>
  </joint>
  <link name="hook__base_mount">
    <inertial>
      <mass value="0.005"/>
      <origin rpy="0  0  0" xyz="0.11    0      0.1355"/>
      <inertia ixx="0.166667" ixy="0" ixz="0" iyy="0.166667" iyz="0" izz="0.166667"/>
    </inertial>
    <collision name="hook__collision">
      <origin rpy="0  0  0" xyz="0.11    0      0.1355"/>
      <geometry>
        <box size="0.03 0.03 0.01"/>
      </geometry>
    </collision>
    <visual name="hook__visual">
      <origin rpy="0  0  0" xyz="0.11    0      0.1355"/>
      <geometry>
        <box size="0.03 0.03 0.01"/>
      </geometry>
    </visual>
  </link>
  <link name="hook__arm">
    <inertial>
      <mass value="0.02"/>
      <origin rpy="0  0  0" xyz="0   0   0.1"/>
      <inertia ixx="0.166667" ixy="0" ixz="0" iyy="0.166667" iyz="0" izz="0.166667"/>
    </inertial>
    <collision name="hook__collision">
      <origin rpy="0  0  0" xyz="0   0   0.1"/>
      <geometry>
        <box size="0.2 0.015 0.015"/>
      </geometry>
    </collision>
    <visual name="hook__visual">
      <origin rpy="0  0  0" xyz="0   0   0.1"/>
      <geometry>
        <box size="0.2 0.015 0.015"/>
      </geometry>
    </visual>
  </link>
  <link name="hook__armjoint">
    <inertial>
      <mass value="0.01"/>
      <origin rpy="0  0  0" xyz="0  0  0"/>
      <inertia ixx="0.145833" ixy="0" ixz="0" iyy="0.145833" iyz="0" izz="0.125"/>
    </inertial>
    <collision name="hook__collision">
      <origin rpy="1.57  0    0" xyz="0  0  0"/>
      <geometry>
        <cylinder length="0.017" radius="0.01"/>
      </geometry>
    </collision>
    <visual name="hook__visual">
      <origin rpy="1.57  0    0" xyz="0  0  0"/>
      <geometry>
        <cylinder length="0.017" radius="0.01"/>
      </geometry>
    </visual>
  </link>
  <link name="hook__base">
    <inertial>
      <mass value="0.01"/>
      <origin rpy="0  0  0" xyz="0  0  0"/>
      <inertia ixx="0.166667" ixy="0" ixz="0" iyy="0.166667" iyz="0" izz="0.166667"/>
    </inertial>
    <collision name="hook__collision">
      <origin rpy="0  0  0" xyz="0  0  0"/>
      <geometry>
        <box size="0.02 0.02 0.023"/>
      </geometry>
    </collision>
    <visual name="hook__visual">
      <origin rpy="0  0  0" xyz="0  0  0"/>
      <geometry>
        <box size="0.02 0.02 0.023"/>
      </geometry>
    </visual>
  </link>
  <link name="hook__basejoint">
    <inertial>
      <mass value="0.01"/>
      <origin rpy="0  0  0" xyz="0  0  0"/>
      <inertia ixx="0.145833" ixy="0" ixz="0" iyy="0.145833" iyz="0" izz="0.125"/>
    </inertial>
    <collision name="hook__collision">
      <origin rpy="1.57  0    0" xyz="0  0  0"/>
      <geometry>
        <cylinder length="0.022" radius="0.013"/>
      </geometry>
    </collision>
    <visual name="hook__visual">
      <origin rpy="1.57  0    0" xyz="0  0  0"/>
      <geometry>
        <cylinder length="0.022" radius="0.013"/>
      </geometry>
    </visual>
  </link>
  <link name="hook__bone1">
    <inertial>
      <mass value="0.01"/>
      <origin rpy="0  0  0" xyz="-0.105  0     0.055"/>
      <inertia ixx="0.166667" ixy="0" ixz="0" iyy="0.166667" iyz="0" izz="0.166667"/>
    </inertial>
    <collision name="hook__collision">
      <origin rpy="0  0  0" xyz="-0.105  0     0.055"/>
      <geometry>
        <box size="0.01 0.01 0.075"/>
      </geometry>
    </collision>
    <visual name="hook__visual">
      <origin rpy="0  0  0" xyz="-0.105  0     0.055"/>
      <geometry>
        <box size="0.01 0.01 0.075"/>
      </geometry>
    </visual>
  </link>
  <link name="hook__bone1joint">
    <inertial>
      <mass value="0.01"/>
      <origin rpy="0  0  0" xyz="0  0  0"/>
      <inertia ixx="0.145833" ixy="0" ixz="0" iyy="0.145833" iyz="0" izz="0.125"/>
    </inertial>
    <collision name="hook__collision">
      <origin rpy="1.57  0    0" xyz="0  0  0"/>
      <geometry>
        <cylinder length="0.012" radius="0.007"/>
      </geometry>
    </collision>
    <visual name="hook__visual">
      <origin rpy="1.57  0    0" xyz="0  0  0"/>
      <geometry>
        <cylinder length="0.012" radius="0.007"/>
      </geometry>
    </visual>
  </link>
  <link name="hook__bone2">
    <inertial>
      <mass value="0.01"/>
      <origin rpy="0  0  0" xyz="-0.075   0      0.0125"/>
      <inertia ixx="0.166667" ixy="0" ixz="0" iyy="0.166667" iyz="0" izz="0.166667"/>
    </inertial>
    <collision name="hook__collision">
      <origin rpy="0  0  0" xyz="-0.075   0      0.0125"/>
      <geometry>
        <box size="0.05 0.01 0.01"/>
      </geometry>
    </collision>
    <visual name="hook__visual">
      <origin rpy="0  0  0" xyz="-0.075   0      0.0125"/>
      <geometry>
        <box size="0.05 0.01 0.01"/>
      </geometry>
    </visual>
  </link>
  <link name="hook__bone2joint">
    <inertial>
      <mass value="0.01"/>
      <origin rpy="0  0  0" xyz="0  0  0"/>
      <inertia ixx="0.145833" ixy="0" ixz="0" iyy="0.145833" iyz="0" izz="0.125"/>
    </inertial>
    <collision name="hook__collision">
      <origin rpy="1.57  0    0" xyz="0  0  0"/>
      <geometry>
        <cylinder length="0.012" radius="0.007"/>
      </geometry>
    </collision>
    <visual name="hook__visual">
      <origin rpy="1.57  0    0" xyz="0  0  0"/>
      <geometry>
        <cylinder length="0.012" radius="0.007"/>
      </geometry>
    </visual>
  </link>
  <link name="hook__bone3">
    <inertial>
      <mass value="0.01"/>
      <origin rpy="0  0  0" xyz="-0.045  0     0.04"/>
      <inertia ixx="0.166667" ixy="0" ixz="0" iyy="0.166667" iyz="0" izz="0.166667"/>
    </inertial>
    <collision name="hook__collision">
      <origin rpy="0  0  0" xyz="-0.045  0     0.04"/>
      <geometry>
        <box size="0.01 0.01 0.045"/>
      </geometry>
    </collision>
    <visual name="hook__visual">
      <origin rpy="0  0  0" xyz="-0.045  0     0.04"/>
      <geometry>
        <box size="0.01 0.01 0.045"/>
      </geometry>
    </visual>
  </link>
  <link name="hook__bone3tip">
    <inertial>
      <mass value="0.01"/>
      <origin rpy="0  0  0" xyz="0  0  0"/>
      <inertia ixx="0.145833" ixy="0" ixz="0" iyy="0.145833" iyz="0" izz="0.125"/>
    </inertial>
    <collision name="hook__collision">
      <origin rpy="1.57  0    0" xyz="0  0  0"/>
      <geometry>
        <cylinder length="0.012" radius="0.005"/>
      </geometry>
    </collision>
    <visual name="hook__visual">
      <origin rpy="1.57  0    0" xyz="0  0  0"/>
      <geometry>
        <cylinder length="0.012" radius="0.005"/>
      </geometry>
    </visual>
  </link>
</robot>
